#VRML_SIM R2025a utf8

EXTERNPROTO "https://raw.githubusercontent.com/cyberbotics/webots/R2025a/projects/objects/backgrounds/protos/TexturedBackground.proto"
EXTERNPROTO "https://raw.githubusercontent.com/cyberbotics/webots/R2025a/projects/objects/backgrounds/protos/TexturedBackgroundLight.proto"
EXTERNPROTO "https://raw.githubusercontent.com/cyberbotics/webots/R2025a/projects/objects/floors/protos/RectangleArena.proto"

WorldInfo {
}
Viewpoint {
  orientation 0.01811589115682665 0.02992421773098783 -0.9993879905626155 1.0892925127687931
  position -0.2590380145701958 0.3347206379509487 0.07077387509676712
}
TexturedBackground {
}
TexturedBackgroundLight {
}
RectangleArena {
}
Robot {
  translation 0 0 0.01
  children [
    BallJoint {
      jointParameters BallJointParameters {
        anchor 0.00422885 -0.0375647 0.001
      }
      jointParameters2 JointParameters {
      }
      jointParameters3 JointParameters {
      }
      endPoint Solid {
        translation 0.00422885 -0.0375647 0.001
        rotation 0.19366103500055568 -0.3515240635313012 -0.9159291655368088 0.32800999999999997
        children [
          DEF ballsocket Shape {
            geometry Sphere {
              radius 0.01
            }
          }
        ]
        name "solid(2)"
        boundingObject USE ballsocket
        physics Physics {
        }
      }
    }
    DEF BODY Pose {
      translation 0 0 0.06
      children [
        Shape {
          appearance PBRAppearance {
          }
          geometry Cylinder {
            height 0.1
            radius 0.05
          }
        }
      ]
    }
    HingeJoint {
      jointParameters HingeJointParameters {
        anchor 0.054992 0.025 0.015008
      }
      device [
        DEF motor1 RotationalMotor {
          name "motor1"
        }
      ]
      endPoint Solid {
        translation 0.054992 0.025 0.015008
        rotation 0 1 0 1.57
        children [
          DEF wheel Shape {
            appearance PBRAppearance {
              baseColor 0.666667 0 0
              metalness 0
            }
            geometry Cylinder {
              height 0.01
              radius 0.025
            }
          }
        ]
        boundingObject USE wheel
        physics DEF wheel_physics Physics {
        }
      }
    }
    HingeJoint {
      jointParameters HingeJointParameters {
        anchor -0.054992 0.025 0.015008
      }
      device [
        RotationalMotor {
          name "motor2"
        }
      ]
      endPoint Solid {
        translation -0.054992 0.025 0.015008
        rotation 0 1 0 1.57
        children [
          USE wheel
        ]
        name "solid(1)"
        boundingObject USE wheel
        physics USE wheel_physics
      }
    }
  ]
  boundingObject USE BODY
  physics Physics {
  }
  controller "basic_controller"
  controllerArgs [
    ""
  ]
}
