#VRML_SIM R2025a utf8

EXTERNPROTO "https://raw.githubusercontent.com/cyberbotics/webots/R2025a/projects/objects/backgrounds/protos/TexturedBackground.proto"
EXTERNPROTO "https://raw.githubusercontent.com/cyberbotics/webots/R2025a/projects/objects/backgrounds/protos/TexturedBackgroundLight.proto"
EXTERNPROTO "https://raw.githubusercontent.com/cyberbotics/webots/R2025a/projects/objects/floors/protos/RectangleArena.proto"

WorldInfo {
}
Viewpoint {
  orientation 0.2535222999678133 -0.5694451594653115 -0.7819582174135367 5.2480158298175095
  position -0.4983086385062233 -0.5983971265947214 0.5704732248238839
}
TexturedBackground {
}
TexturedBackgroundLight {
}
RectangleArena {
}
Robot {
  children [
    DEF BODY Pose {
      translation 0 0 0.06
      children [
        Shape {
          appearance PBRAppearance {
          }
          geometry Cylinder {
            height 0.1
            radius 0.05
          }
        }
      ]
    }
    HingeJoint {
      jointParameters HingeJointParameters {
        anchor 0.055 0 0.025
      }
      device [
        DEF motor1 RotationalMotor {
          name "motor1"
        }
      ]
      endPoint Solid {
        translation 0.055 0 0.025008
        rotation 0 1 0 1.57
        children [
          DEF wheel Shape {
            appearance PBRAppearance {
              baseColor 0.666667 0 0
              metalness 0
            }
            geometry Cylinder {
              height 0.01
              radius 0.025
            }
          }
        ]
        boundingObject USE wheel
        physics DEF wheel_physics Physics {
        }
      }
    }
    HingeJoint {
      jointParameters HingeJointParameters {
        anchor 0.055 0 0.025
      }
      device [
        RotationalMotor {
          name "motor2"
        }
      ]
      endPoint Solid {
        translation -0.055 0 0.025008
        rotation 0 1 0 1.57
        children [
          USE wheel
        ]
        name "solid(1)"
        boundingObject USE wheel
        physics USE wheel_physics
      }
    }
  ]
  boundingObject USE BODY
  physics Physics {
  }
}
